<?xml version="1.0" encoding="UTF-8"?>
<!-- Generated by org.testng.reporters.JUnitReportReporter -->
<testsuite hostname="ajay-PC" name="com.abtrading.zoho.project.testcases.LoginTest" tests="2" failures="1" timestamp="4 Jul 2017 04:32:58 GMT" time="237.472" errors="0">
  <testcase name="doLogin" time="163.405" classname="com.abtrading.zoho.project.testcases.LoginTest"/>
  <testcase name="doLogin" time="74.067" classname="com.abtrading.zoho.project.testcases.LoginTest">
    <failure type="java.lang.AssertionError" message="Login Test Failed.">
      <![CDATA[java.lang.AssertionError: Login Test Failed.
	at org.testng.Assert.fail(Assert.java:94)
	at com.abtrading.zoho.project.base.BaseTest.reportFail(BaseTest.java:274)
	at com.abtrading.zoho.project.testcases.LoginTest.doLogin(LoginTest.java:57)
	at sun.reflect.NativeMethodAccessorImpl.invoke0(Native Method)
	at sun.reflect.NativeMethodAccessorImpl.invoke(Unknown Source)
	at sun.reflect.DelegatingMethodAccessorImpl.invoke(Unknown Source)
	at java.lang.reflect.Method.invoke(Unknown Source)
	at org.testng.internal.MethodInvocationHelper.invokeMethod(MethodInvocationHelper.java:85)
	at org.testng.internal.Invoker.invokeMethod(Invoker.java:639)
	at org.testng.internal.Invoker.invokeTestMethod(Invoker.java:821)
	at org.testng.internal.TestMethodWithDataProviderMethodWorker.call(TestMethodWithDataProviderMethodWorker.java:75)
	at org.testng.internal.TestMethodWithDataProviderMethodWorker.call(TestMethodWithDataProviderMethodWorker.java:14)
	at java.util.concurrent.FutureTask.run(Unknown Source)
	at java.util.concurrent.Executors$RunnableAdapter.call(Unknown Source)
	at java.util.concurrent.FutureTask.run(Unknown Source)
	at java.util.concurrent.ThreadPoolExecutor.runWorker(Unknown Source)
	at java.util.concurrent.ThreadPoolExecutor$Worker.run(Unknown Source)
	at java.lang.Thread.run(Unknown Source)
]]>
    </failure>
  </testcase> <!-- doLogin -->
</testsuite> <!-- com.abtrading.zoho.project.testcases.LoginTest -->
